Workbook

Sheet สรุป
B2: ใบตรวจราคา mstgolf.co.th
B3: ข้อมูลสินค้าดึงจากหน้าเว็บสาธารณะ mstgolf.co.th และ mstgolf.com.sg (products.json) เมื่อ 27 ก.ย. 2026 · จัดทำโดย ORIONS
B5: ค่าที่ใช้คำนวณ
B6: อัตราแลกเปลี่ยนอ้างอิง (บาท ต่อ 1 SGD) | C6: 25 | D6: ตัวเลขตัวอย่าง — แก้เป็นอัตราวันที่ตรวจ ใช้แค่คอลัมน์ N ในแท็บ สินค้า
B8: สิ่งที่พบ
B9: สินค้าบน mstgolf.co.th | C9: =COUNTA('สินค้า'!$C$2:$C$5575) | D9: นับเป็นรายการสินค้า (ตัวเลือกไซส์/สีรวมอยู่ในรายการเดียว)
B10: สินค้าที่มีสต็อกบนเว็บ | C10: =COUNTIF('สินค้า'!$I$2:$I$5575,"มี")
B11: สินค้าที่พบในร้านสิงคโปร์ (SKU เดียวกัน) | C11: =COUNTIF('สินค้า'!$M$2:$M$5575,"<>ไม่พบใน SG")
B12: ในจำนวนนั้น ราคาตรงกับร้านสิงคโปร์ทุกตัวเลข | C12: =COUNTIF('สินค้า'!$M$2:$M$5575,"ตรงกัน") | D12: ตัวเลขเดียวกับราคา SGD แต่แสดงเป็นบาท
B13: สัดส่วนที่ราคาตรงกับร้านสิงคโปร์ | C13: =IFERROR(C12/C11,0)
B14: ราคากลางของสินค้าทั้งหมดบนเว็บ (฿) | C14: =MEDIAN('สินค้า'!$J$2:$J$5575) | D14: ร้านกอล์ฟในไทยไม่มีราคากลางระดับนี้
B15: ราคากลางของไม้กอล์ฟ (฿) | C15: =MEDIAN('สินค้า'!$T$2:$T$5575) | D15: เช่น ไดรเวอร์ PING G425 แสดง ฿699
B16: สินค้าที่ราคาเป็น 0 | C16: =COUNTIF('สินค้า'!$J$2:$J$5575,0)
B18: สรุป: ราคาบน mstgolf.co.th เป็นราคาร้านสิงคโปร์ (SGD) ที่ใส่สัญลักษณ์บาท ต้องใส่ราคาบาทจริงก่อนเปิดขาย
B20: วิธีใช้
B21: 1. แท็บ แบรนด์ — ระบุว่าแบรนด์ไหนขายออนไลน์ในไทยได้ และใครเป็นผู้แทน (ช่องสีเหลือง)
B22: 2. แท็บ สินค้า — เรียงตามลำดับตรวจ: 1 = ไม้กอล์ฟและอุปกรณ์วัดระยะ · 2 = รองเท้า ถุง ลูก ถุงมือ รถเข็น · 3 = เสื้อผ้าและอุปกรณ์เสริม
B23: 3. กรอกเฉพาะช่องสีเหลือง: ราคาขายไทย · ราคาเต็มก่อนลด (ถ้ามีโปร) · ขายในไทย? · หมายเหตุ
B24: 4. สินค้าที่ยังไม่มีราคาไทย ให้ใส่ ไม่ขาย — ORIONS จะซ่อนจากเว็บจนกว่าจะมีราคา
B25: 5. ถ้าช่อง ราคาในตัวเลือก ขึ้นว่า ต่างกัน แปลว่าไซส์/สเปกมีราคาไม่เท่ากัน ให้เขียนราคาแต่ละแบบในหมายเหตุ
B26: ช่องสีเหลือง ตัวอักษรสีน้ำเงิน = ช่องที่ MST กรอก · ตัวอักษรสีเขียว = คำนวณจากแท็บอื่น · ที่เหลือเป็นข้อมูลจากเว็บ ไม่ต้องแก้
B28: ตัวอย่างการกรอก (ไม่ใช่ข้อมูลจริง)
B29: ชื่อสินค้า | C29: ราคาขายไทย (฿) | D29: ราคาเต็มก่อนลด (฿) · ขายในไทย? · หมายเหตุ
B30: PING G425 Max Men's Driver | C30: 15900 | D30: 18,900 · ขาย · ก้าน Regular และ Stiff ราคาเดียวกัน

Sheet สินค้า
A1: ลำดับตรวจ | B1: หมวด | C1: Handle | D1: ชื่อสินค้า | E1: แบรนด์ | F1: ประเภท (ร้านกลุ่ม) | G1: SKU | H1: ตัวเลือก | I1: สต็อกบนเว็บ | J1: ราคาที่แสดงตอนนี้ (฿) | K1: ราคาในตัวเลือก | L1: ราคาร้าน SG (SGD) | M1: เทียบราคา SG | N1: ประมาณ ฿ จากราคา SG (อ้างอิง) | O1: ราคาขายไทย (฿) | P1: ราคาเต็มก่อนลด (฿) | Q1: ขายในไทย? | R1: หมายเหตุ | S1: ลิงก์ | T1: ช่วยคำนวณ
A2: 1 | B2: ไม้กอล์ฟ | C2: gf1250100182 | D2: MAJESTY HER MAJESTY (2023) Women's Package Set | E2: MAJESTY | F2: PACKAGE SET | G2: GF1250100182 | H2: 1 | I2: มี | J2: 17700 | L2: 17700 | M2: =IF(L2="","ไม่พบใน SG",IF(ABS(J2-L2)<0.005,"ตรงกัน","ไม่ตรง")) | N2: =IF(L2="","",ROUND(L2*'สรุป'!$C$6,-1)) | S2: https://mstgolf.co.th/products/gf1250100182 | T2: =IF(B2="ไม้กอล์ฟ",J2,"")
A3: 1 | B3: ไม้กอล์ฟ | C3: gf1250100165 | D3: TAYLORMADE Stealth Gloire Graphite (2023) Men's Package Set | E3: TAYLORMADE | F3: PACKAGE SET | G3: GF1250100165R | H3: 1 | I3: มี | J3: 5900 | M3: =IF(L3="","ไม่พบใน SG",IF(ABS(J3-L3)<0.005,"ตรงกัน","ไม่ตรง")) | N3: =IF(L3="","",ROUND(L3*'สรุป'!$C$6,-1)) | S3: https://mstgolf.co.th/products/gf1250100165 | T3: =IF(B3="ไม้กอล์ฟ",J3,"")
A4: 1 | B4: ไม้กอล์ฟ | C4: gf1210101111 | D4: MAJESTY Prestigio 13 Merlion LE (2024) Men's Driver | E4: MAJESTY | F4: DRIVER | G4: GF1210101111105R | H4: 2 | I4: มี | J4: 2590 | M4: =IF(L4="","ไม่พบใน SG",IF(ABS(J4-L4)<0.005,"ตรงกัน","ไม่ตรง")) | N4: =IF(L4="","",ROUND(L4*'สรุป'!$C$6,-1)) | S4: https://mstgolf.co.th/products/gf1210101111 | T4: =IF(B4="ไม้กอล์ฟ",J4,"")
A5: 1 | B5: ไม้กอล์ฟ | C5: gf1250100195 | D5: TAYLORMADE Kalea Gold (2024) Women's Package Set | E5: TAYLORMADE | F5: PACKAGE SET | G5: GF1250100195 | H5: 1 | I5: มี | J5: 2590 | L5: 2590 | M5: =IF(L5="","ไม่พบใน SG",IF(ABS(J5-L5)<0.005,"ตรงกัน","ไม่ตรง")) | N5: =IF(L5="","",ROUND(L5*'สรุป'!$C$6,-1)) | S5: https://mstgolf.co.th/products/gf1250100195 | T5: =IF(B5="ไม้กอล์ฟ",J5,"")
A6: 1 | B6: ไม้กอล์ฟ | C6: gf1280101355 | D6: TAYLORMADE P790 Satin Charcoal (2025) Men's Irons | E6: TAYLORMADE | F6: SET OF IRONS | G6: GF1280101355S | H6: 1 | I6: มี | J6: 2150 | L6: 2150 | M6: =IF(L6="","ไม่พบใน SG",IF(ABS(J6-L6)<0.005,"ตรงกัน","ไม่ตรง")) | N6: =IF(L6="","",ROUND(L6*'สรุป'!$C$6,-1)) | S6: https://mstgolf.co.th/products/gf1280101355 | T6: =IF(B6="ไม้กอล์ฟ",J6,"")
A7: 1 | B7: ไม้กอล์ฟ | C7: gf1280101388 | D7: TITLEIST T100 (2025) Men's Irons | E7: TITLEIST | F7: SET OF IRONS | G7: GF1280101389S | H7: 2 | I7: มี | J7: 2059 | L7: 2059 | M7: =IF(L7="","ไม่พบใน SG",IF(ABS(J7-L7)<0.005,"ตรงกัน","ไม่ตรง")) | N7: =IF(L7="","",ROUND(L7*'สรุป'!$C$6,-1)) | S7: https://mstgolf.co.th/products/gf1280101388 | T7: =IF(B7="ไม้กอล์ฟ",J7,"")
A8: 1 | B8: ไม้กอล์ฟ | C8: gf1280101395 | D8: TITLEIST T350 (2025) Men's Irons | E8: TITLEIST | F8: SET OF IRONS | G8: GF1280101395R | H8: 4 | I8: มี | J8: 2059 | K8: ต่างกัน | L8: 2059 | M8: =IF(L8="","ไม่พบใน SG",IF(ABS(J8-L8)<0.005,"ตรงกัน","ไม่ตรง")) | N8: =IF(L8="","",ROUND(L8*'สรุป'!$C$6,-1)) | S8: https://mstgolf.co.th/products/gf1280101395 | T8: =IF(B8="ไม้กอล์ฟ",J8,"")
A9: 1 | B9: ไม้กอล์ฟ | C9: gf1250100163 | D9: TAYLORMADE Kalea Navy/Light Grey (2022) Women's Package Set | E9: TAYLORMADE | F9: PACKAGE SET | G9: GF1250100163 | H9: 1 | I9: มี | J9: 2050 | L9: 2050 | M9: =IF(L9="","ไม่พบใน SG",IF(ABS(J9-L9)<0.005,"ตรงกัน","ไม่ตรง")) | N9: =IF(L9="","",ROUND(L9*'สรุป'!$C$6,-1)) | S9: https://mstgolf.co.th/products/gf1250100163 | T9: =IF(B9="ไม้กอล์ฟ",J9,"")
A10: 1 | B10: ไม้กอล์ฟ | C10: gf1280101221 | D10: TAYLORMADE P770 (2024) Men's Irons | E10: TAYLORMADE | F10: SET OF IRONS | G10: GF1280101222S | H10: 3 | I10: มี | J10: 2050 | L10: 2050 | M10: =IF(L10="","ไม่พบใน SG",IF(ABS(J10-L10)<0.005,"ตรงกัน","ไม่ตรง")) | N10: =IF(L10="","",ROUND(L10*'สรุป'!$C$6,-1)) | S10: https://mstgolf.co.th/products/gf1280101221 | T10: =IF(B10="ไม้กอล์ฟ",J10,"")
A11: 1 | B11: ไม้กอล์ฟ | C11: gf1280101304 | D11: TAYLORMADE P790 (2025) Men's Irons | E11: TAYLORMADE | F11: SET OF IRONS | G11: GF1280101307S | H11: 5 | I11: มี | J11: 2050 | K11: ต่างกัน | L11: 2050 | M11: =IF(L11="","ไม่พบใน SG",IF(ABS(J11-L11)<0.005,"ตรงกัน","ไม่ตรง")) | N11: =IF(L11="","",ROUND(L11*'สรุป'!$C$6,-1)) | S11: https://mstgolf.co.th/products/gf1280101304 | T11: =IF(B11="ไม้กอล์ฟ",J11,"")
A12: 1 | B12: ไม้กอล์ฟ | C12: gf1280101223 | D12: TAYLORMADE P7CB (2024) Men's Irons | E12: TAYLORMADE | F12: SET OF IRONS | G12: GF1280101223S | H12: 1 | I12: มี | J12: 2050 | L12: 2050 | M12: =IF(L12="","ไม่พบใน SG",IF(ABS(J12-L12)<0.005,"ตรงกัน","ไม่ตรง")) | N12: =IF(L12="","",ROUND(L12*'สรุป'!$C$6,-1)) | S12: https://mstgolf.co.th/products/gf1280101223 | T12: =IF(B12="ไม้กอล์ฟ",J12,"")
A13: 1 | B13: ไม้กอล์ฟ | C13: gf1280101245 | D13: YAMAHA Inpres DriveStar Type/D (2025) Men's Irons | E13: YAMAHA | F13: SET OF IRONS | G13: GF1280101245R | H13: 2 | I13: มี | J13: 2050 | L13: 990 | M13: =IF(L13="","ไม่พบใน SG",IF(ABS(J13-L13)<0.005,"ตรงกัน","ไม่ตรง")) | N13: =IF(L13="","",ROUND(L13*'สรุป'!$C$6,-1)) | S13: https://mstgolf.co.th/products/gf1280101245 | T13: =IF(B13="ไม้กอล์ฟ",J13,"")
A14: 1 | B14: ไม้กอล์ฟ | C14: gf1280101246 | D14: YAMAHA Inpres DriveStar Type/S (2025) Men's Irons | E14: YAMAHA | F14: SET OF IRONS | G14: GF1280101246S | H14: 1 | I14: มี | J14: 2050 | L14: 990 | M14: =IF(L14="","ไม่พบใน SG",IF(ABS(J14-L14)<0.005,"ตรงกัน","ไม่ตรง")) | N14: =IF(L14="","",ROUND(L14*'สรุป'!$C$6,-1)) | S14: https://mstgolf.co.th/products/gf1280101246 | T14: =IF(B14="ไม้กอล์ฟ",J14,"")
A15: 1 | B15: ไม้กอล์ฟ | C15: gf1280101158 | D15: PING Blueprint S (2024) Men's Irons | E15: PING | F15: SET OF IRONS | G15: GF1280101158S | H15: 1 | I15: มี | J15: 1930 | L15: 1930 | M15: =IF(L15="","ไม่พบใน SG",IF(ABS(J15-L15)<0.005,"ตรงกัน","ไม่ตรง")) | N15: =IF(L15="","",ROUND(L15*'สรุป'!$C$6,-1)) | S15: https://mstgolf.co.th/products/gf1280101158 | T15: =IF(B15="ไม้กอล์ฟ",J15,"")
A16: 1 | B16: ไม้กอล์ฟ | C16: gf1280101159 | D16: PING Blueprint T (2024) Men's Irons | E16: PING | F16: SET OF IRONS | G16: GF1280101159S | H16: 1 | I16: มี | J16: 1930 | L16: 1930 | M16: =IF(L16="","ไม่พบใน SG",IF(ABS(J16-L16)<0.005,"ตรงกัน","ไม่ตรง")) | N16: =IF(L16="","",ROUND(L16*'สรุป'!$C$6,-1)) | S16: https://mstgolf.co.th/products/gf1280101159 | T16: =IF(B16="ไม้กอล์ฟ",J16,"")
A17: 1 | B17: ไม้กอล์ฟ | C17: gf1280101381 | D17: MIZUNO Pro M-15 (2026) Men's Irons | E17: MIZUNO | F17: SET OF IRONS | G17: GF1280101381S | H17: 2 | I17: มี | J17: 1870 | L17: 1870 | M17: =IF(L17="","ไม่พบใน SG",IF(ABS(J17-L17)<0.005,"ตรงกัน","ไม่ตรง")) | N17: =IF(L17="","",ROUND(L17*'สรุป'!$C$6,-1)) | S17: https://mstgolf.co.th/products/gf1280101381 | T17: =IF(B17="ไม้กอล์ฟ",J17,"")
A18: 1 | B18: ไม้กอล์ฟ | C18: gf1250100218 | D18: TAYLORMADE RBZ (2025) Graphite Men's Package Set | E18: TAYLORMADE | F18: PACKAGE SET | G18: GF1250100218R | H18: 1 | I18: มี | J18: 1850 | L18: 1850 | M18: =IF(L18="","ไม่พบใน SG",IF(ABS(J18-L18)<0.005,"ตรงกัน","ไม่ตรง")) | N18: =IF(L18="","",ROUND(L18*'สรุป'!$C$6,-1)) | S18: https://mstgolf.co.th/products/gf1250100218 | T18: =IF(B18="ไม้กอล์ฟ",J18,"")
A19: 1 | B19: ไม้กอล์ฟ | C19: gf1280101156 | D19: PING I530 (2024) Men's Irons | E19: PING | F19: SET OF IRONS | G19: GF1280101157S | H19: 3 | I19: มี | J19: 1790 | K19: ต่างกัน | L19: 1450 | M19: =IF(L19="","ไม่พบใน SG",IF(ABS(J19-L19)<0.005,"ตรงกัน","ไม่ตรง")) | N19: =IF(L19="","",ROUND(L19*'สรุป'!$C$6,-1)) | S19: https://mstgolf.co.th/products/gf1280101156 | T19: =IF(B19="ไม้กอล์ฟ",J19,"")
A20: 1 | B20: ไม้กอล์ฟ | C20: gf1280101281 | D20: ONOFF LP425I (2025) Women's Irons | E20: ONOFF | F20: SET OF IRONS | G20: GF1280101282L | H20: 4 | I20: มี | J20: 1750 | L20: 1750 | M20: =IF(L20="","ไม่พบใน SG",IF(ABS(J20-L20)<0.005,"ตรงกัน","ไม่ตรง")) | N20: =IF(L20="","",ROUND(L20*'สรุป'!$C$6,-1)) | S20: https://mstgolf.co.th/products/gf1280101281 | T20: =IF(B20="ไม้กอล์ฟ",J20,"")
A21: 1 | B21: ไม้กอล์ฟ | C21: gf1280101284 | D21: ONOFF LP425I Green (2025) Women's Irons | E21: ONOFF | F21: SET OF IRONS | G21: GF1280101284L | H21: 1 | I21: มี | J21: 1750 | L21: 1750 | M21: =IF(L21="","ไม่พบใน SG",IF(ABS(J21-L21)<0.005,"ตรงกัน","ไม่ตรง")) | N21: =IF(L21="","",ROUND(L21*'สรุป'!$C$6,-1)) | S21: https://mstgolf.co.th/products/gf1280101284 | T21: =IF(B21="ไม้กอล์ฟ",J21,"")
A22: 1 | B22: ไม้กอล์ฟ | C22: gf1280101283 | D22: ONOFF LP425I Pink (2025) Women's Irons | E22: ONOFF | F22: SET OF IRONS | G22: GF1280101283L | H22: 1 | I22: มี | J22: 1750 | L22: 1750 | M22: =IF(L22="","ไม่พบใน SG",IF(ABS(J22-L22)<0.005,"ตรงกัน","ไม่ตรง")) | N22: =IF(L22="","",ROUND(L22*'สรุป'!$C$6,-1)) | S22: https://mstgolf.co.th/products/gf1280101283 | T22: =IF(B22="ไม้กอล์ฟ",J22,"")
A23: 1 | B23: ไม้กอล์ฟ | C23: gf1280101247 | D23: YAMAHA Inpres DriveStar (2025) Women's Irons | E23: YAMAHA | F23: SET OF IRONS | G23: GF1280101247L | H23: 1 | I23: มี | J23: 1750 | L23: 850 | M23: =IF(L23="","ไม่พบใน SG",IF(ABS(J23-L23)<0.005,"ตรงกัน","ไม่ตรง")) | N23: =IF(L23="","",ROUND(L23*'สรุป'!$C$6,-1)) | S23: https://mstgolf.co.th/products/gf1280101247 | T23: =IF(B23="ไม้กอล์ฟ",J23,"")
A24: 1 | B24: ไม้กอล์ฟ | C24: gf1280101160 | D24: PING G730 (2024) Men's Irons | E24: PING | F24: SET OF IRONS | G24: GF1280101161R | H24: 2 | I24: มี | J24: 1690 | K24: ต่างกัน | L24: 1690 | M24: =IF(L24="","ไม่พบใน SG",IF(ABS(J24-L24)<0.005,"ตรงกัน","ไม่ตรง")) | N24: =IF(L24="","",ROUND(L24*'สรุป'!$C$6,-1)) | S24: https://mstgolf.co.th/products/gf1280101160 | T24: =IF(B24="ไม้กอล์ฟ",J24,"")
A25: 1 | B25: ไม้กอล์ฟ | C25: gf1250100219 | D25: TAYLORMADE RBZ (2025) Steel Men's Package Set | E25: TAYLORMADE | F25: PACKAGE SET | G25: GF1250100219R | H25: 1 | I25: มี | J25: 1690 | L25: 1690 | M25: =IF(L25="","ไม่พบใน SG",IF(ABS(J25-L25)<0.005,"ตรงกัน","ไม่ตรง")) | N25: =IF(L25="","",ROUND(L25*'สรุป'!$C$6,-1)) | S25: https://mstgolf.co.th/products/gf1250100219 | T25: =IF(B25="ไม้กอล์ฟ",J25,"")
A26: 1 | B26: ไม้กอล์ฟ | C26: gf1280101105 | D26: YAMAHA RMX VD/X (2024) Men's Irons (8 Clubs) | E26: YAMAHA | F26: SET OF IRONS | G26: GF1280101106SR | H26: 4 | I26: มี | J26: 1650 | K26: ต่างกัน | L26: 825 | M26: =IF(L26="","ไม่พบใน SG",IF(ABS(J26-L26)<0.005,"ตรงกัน","ไม่ตรง")) | N26: =IF(L26="","",ROUND(L26*'สรุป'!$C$6,-1)) | S26: https://mstgolf.co.th/products/gf1280101105 | T26: =IF(B26="ไม้กอล์ฟ",J26,"")
A27: 1 | B27: ไม้กอล์ฟ | C27: gf1280101131 | D27: CALLAWAY Apex Pro (2024) Men's Irons | E27: CALLAWAY | F27: SET OF IRONS | G27: GF1280101131S | H27: 1 | I27: มี | J27: 1647 | L27: 1647 | M27: =IF(L27="","ไม่พบใน SG",IF(ABS(J27-L27)<0.005,"ตรงกัน","ไม่ตรง")) | N27: =IF(L27="","",ROUND(L27*'สรุป'!$C$6,-1)) | S27: https://mstgolf.co.th/products/gf1280101131 | T27: =IF(B27="ไม้กอล์ฟ",J27,"")
A28: 1 | B28: ไม้กอล์ฟ | C28: gf1280100966 | D28: MARUMAN SG M230 (2023) Women's Irons | E28: MARUMAN | F28: SET OF IRONS | G28: GF1280100966L | H28: 1 | I28: มี | J28: 1590 | L28: 1590 | M28: =IF(L28="","ไม่พบใน SG",IF(ABS(J28-L28)<0.005,"ตรงกัน","ไม่ตรง")) | N28: =IF(L28="","",ROUND(L28*'สรุป'!$C$6,-1)) | S28: https://mstgolf.co.th/products/gf1280100966 | T28: =IF(B28="ไม้กอล์ฟ",J28,"")
A29: 1 | B29: ไม้กอล์ฟ | C29: gf1280101300 | D29: PING G440 HL (2025) Men's Irons | E29: PING | F29: SET OF IRONS | G29: GF1280101300 | H29: 1 | I29: มี | J29: 1590 | M29: =IF(L29="","ไม่พบใน SG",IF(ABS(J29-L29)<0.005,"ตรงกัน","ไม่ตรง")) | N29: =IF(L29="","",ROUND(L29*'สรุป'!$C$6,-1)) | S29: https://mstgolf.co.th/products/gf1280101300 | T29: =IF(B29="ไม้กอล์ฟ",J29,"")
A30: 1 | B30: ไม้กอล์ฟ | C30: gf1280101420 | D30: TAYLORMADE Qi Max (2026) Men's Irons | E30: TAYLORMADE | F30: SET OF IRONS | G30: GF1280101423R | H30: 6 | I30: มี | J30: 1590 | K30: ต่างกัน | L30: 1590 | M30: =IF(L30="","ไม่พบใน SG",IF(ABS(J30-L30)<0.005,"ตรงกัน","ไม่ตรง")) | N30: =IF(L30="","",ROUND(L30*'สรุป'!$C$6,-1)) | S30: https://mstgolf.co.th/products/gf1280101420 | T30: =IF(B30="ไม้กอล์ฟ",J30,"")
A31: 1 | B31: ไม้กอล์ฟ | C31: gf1280101237 | D31: MIZUNO JPX-925 Forged (2024) Men's Irons | E31: MIZUNO | F31: SET OF IRONS | G31: GF1280101238R | H31: 4 | I31: มี | J31: 1550 | L31: 1130 | M31: =IF(L31="","ไม่พบใน SG",IF(ABS(J31-L31)<0.005,"ตรงกัน","ไม่ตรง")) | N31: =IF(L31="","",ROUND(L31*'สรุป'!$C$6,-1)) | S31: https://mstgolf.co.th/products/gf1280101237 | T31: =IF(B31="ไม้กอล์ฟ",J31,"")
A32: 1 | B32: ไม้กอล์ฟ | C32: gf1240101199 | D32: TITLEIST SC Concept x 7.2 Limited Edition Men's Putter (2023) | E32: TITLEIST | F32: PUTTER | G32: GF124010120034 | H32: 1 | I32: มี | J32: 1500 | L32: 1500 | M32: =IF(L32="","ไม่พบใน SG",IF(ABS(J32-L32)<0.005,"ตรงกัน","ไม่ตรง")) | N32: =IF(L32="","",ROUND(L32*'สรุป'!$C$6,-1)) | S32: https://mstgolf.co.th/products/gf1240101199 | T32: =IF(B32="ไม้กอล์ฟ",J32,"")
A33: 1 | B33: ไม้กอล์ฟ | C33: gf1280101149 | D33: ONOFF KURO Forged (2024) Men's Irons | E33: ONOFF | F33: SET OF IRONS | G33: GF1280101149S | H33: 3 | I33: มี | J33: 1450 | K33: ต่างกัน | L33: 1190 | M33: =IF(L33="","ไม่พบใน SG",IF(ABS(J33-L33)<0.005,"ตรงกัน","ไม่ตรง")) | N33: =IF(L33="","",ROUND(L33*'สรุป'!$C$6,-1)) | S33: https://mstgolf.co.th/products/gf1280101149 | T33: =IF(B33="ไม้กอล์ฟ",J33,"")
A34: 1 | B34: ไม้กอล์ฟ | C34: gf1280101298 | D34: PING G440 (2025) Men's Irons | E34: PING | F34: SET OF IRONS | G34: GF1280101298R | H34: 2 | I34: มี | J34: 1450 | K34: ต่างกัน | L34: 1450 | M34: =IF(L34="","ไม่พบใน SG",IF(ABS(J34-L34)<0.005,"ตรงกัน","ไม่ตรง")) | N34: =IF(L34="","",ROUND(L34*'สรุป'!$C$6,-1)) | S34: https://mstgolf.co.th/products/gf1280101298 | T34: =IF(B34="ไม้กอล์ฟ",J34,"")
A35: 1 | B35: ไม้กอล์ฟ | C35: gf1210101236 | D35: MAJESTY Royale (2025) Men's Driver | E35: MAJESTY | F35: DRIVER | G35: GF1210101236105R | H35: 2 | I35: มี | J35: 1390 | L35: 1390 | M35: =IF(L35="","ไม่พบใน SG",IF(ABS(J35-L35)<0.005,"ตรงกัน","ไม่ตรง")) | N35: =IF(L35="","",ROUND(L35*'สรุป'!$C$6,-1)) | S35: https://mstgolf.co.th/products/gf1210101236 | T35: =IF(B35="ไม้กอล์ฟ",J35,"")
A36: 1 | B36: ไม้กอล์ฟ | C36: gf1280101309 | D36: TAYLORMADE Qi Max Lite (2025) Men's Irons | E36: TAYLORMADE | F36: SET OF IRONS | G36: GF1280101311R | H36: 2 | I36: มี | J36: 1390 | K36: ต่างกัน | L36: 1090 | M36: =IF(L36="","ไม่พบใน SG",IF(ABS(J36-L36)<0.005,"ตรงกัน","ไม่ตรง")) | N36: =IF(L36="","",ROUND(L36*'สรุป'!$C$6,-1)) | S36: https://mstgolf.co.th/products/gf1280101309 | T36: =IF(B36="ไม้กอล์ฟ",J36,"")
A37: 1 | B37: ไม้กอล์ฟ | C37: gf1280101425 | D37: TAYLORMADE Qi Max Lite (2026) Men's Irons | E37: TAYLORMADE | F37: SET OF IRONS | G37: GF1280101426S | H37: 3 | I37: มี | J37: 1350 | K37: ต่างกัน | L37: 1350 | M37: =IF(L37="","ไม่พบใน SG",IF(ABS(J37-L37)<0.005,"ตรงกัน","ไม่ตรง")) | N37: =IF(L37="","",ROUND(L37*'สรุป'!$C$6,-1)) | S37: https://mstgolf.co.th/products/gf1280101425 | T37: =IF(B37="ไม้กอล์ฟ",J37,"")
A38: 1 | B38: ไม้กอล์ฟ | C38: gf1280101240 | D38: MIZUNO JPX-925 Hot Metal (2024) Men's Irons | E38: MIZUNO | F38: SET OF IRONS | G38: GF1280101241R | H38: 3 | I38: มี | J38: 1330 | L38: 990 | M38: =IF(L38="","ไม่พบใน SG",IF(ABS(J38-L38)<0.005,"ตรงกัน","ไม่ตรง")) | N38: =IF(L38="","",ROUND(L38*'สรุป'!$C$6,-1)) | S38: https://mstgolf.co.th/products/gf1280101240 | T38: =IF(B38="ไม้กอล์ฟ",J38,"")
A39: 1 | B39: ไม้กอล์ฟ | C39: gf1250100214 | D39: COBRA Fly XL (2021) Women's Package Set | E39: COBRA | F39: PACKAGE SET | G39: GF1250100214 | H39: 1 | I39: มี | J39: 1290 | M39: =IF(L39="","ไม่พบใน SG",IF(ABS(J39-L39)<0.005,"ตรงกัน","ไม่ตรง")) | N39: =IF(L39="","",ROUND(L39*'สรุป'!$C$6,-1)) | S39: https://mstgolf.co.th/products/gf1250100214 | T39: =IF(B39="ไม้กอล์ฟ",J39,"")
A40: 1 | B40: ไม้กอล์ฟ | C40: gf1220100795 | D40: MAJESTY Prestigio 13 (2024) Men's Fairway | E40: MAJESTY | F40: FAIRWAY WOOD | G40: GF1220100795#3R | H40: 6 | I40: มี | J40: 1290 | L40: 1290 | M40: =IF(L40="","ไม่พบใน SG",IF(ABS(J40-L40)<0.005,"ตรงกัน","ไม่ตรง")) | N40: =IF(L40="","",ROUND(L40*'สรุป'!$C$6,-1)) | S40: https://mstgolf.co.th/products/gf1220100795 | T40: =IF(B40="ไม้กอล์ฟ",J40,"")
...

Sheet แบรนด์
A1: แบรนด์ | B1: จำนวนสินค้า | C1: มีสต็อกบนเว็บ | D1: ราคาตรงกับ SG | E1: มีสิทธิ์ขายออนไลน์ในไทย? | F1: ผู้แทน/ผู้นำเข้าในไทย | G1: นโยบายราคา (ถ้ามี) | H1: หมายเหตุ
A2: ADIDAS | B2: =COUNTIF('สินค้า'!$E$2:$E$5575,A2) | C2: =COUNTIFS('สินค้า'!$E$2:$E$5575,A2,'สินค้า'!$I$2:$I$5575,"มี") | D2: =COUNTIFS('สินค้า'!$E$2:$E$5575,A2,'สินค้า'!$M$2:$M$5575,"ตรงกัน")
A3: TAYLORMADE | B3: =COUNTIF('สินค้า'!$E$2:$E$5575,A3) | C3: =COUNTIFS('สินค้า'!$E$2:$E$5575,A3,'สินค้า'!$I$2:$I$5575,"มี") | D3: =COUNTIFS('สินค้า'!$E$2:$E$5575,A3,'สินค้า'!$M$2:$M$5575,"ตรงกัน")
A4: PUMA | B4: =COUNTIF('สินค้า'!$E$2:$E$5575,A4) | C4: =COUNTIFS('สินค้า'!$E$2:$E$5575,A4,'สินค้า'!$I$2:$I$5575,"มี") | D4: =COUNTIFS('สินค้า'!$E$2:$E$5575,A4,'สินค้า'!$M$2:$M$5575,"ตรงกัน")
A5: GFORE | B5: =COUNTIF('สินค้า'!$E$2:$E$5575,A5) | C5: =COUNTIFS('สินค้า'!$E$2:$E$5575,A5,'สินค้า'!$I$2:$I$5575,"มี") | D5: =COUNTIFS('สินค้า'!$E$2:$E$5575,A5,'สินค้า'!$M$2:$M$5575,"ตรงกัน")
A6: UNDER ARMOUR | B6: =COUNTIF('สินค้า'!$E$2:$E$5575,A6) | C6: =COUNTIFS('สินค้า'!$E$2:$E$5575,A6,'สินค้า'!$I$2:$I$5575,"มี") | D6: =COUNTIFS('สินค้า'!$E$2:$E$5575,A6,'สินค้า'!$M$2:$M$5575,"ตรงกัน")
A7: LE COQ SPORTIF GOLF | B7: =COUNTIF('สินค้า'!$E$2:$E$5575,A7) | C7: =COUNTIFS('สินค้า'!$E$2:$E$5575,A7,'สินค้า'!$I$2:$I$5575,"มี") | D7: =COUNTIFS('สินค้า'!$E$2:$E$5575,A7,'สินค้า'!$M$2:$M$5575,"ตรงกัน")
A8: TITLEIST | B8: =COUNTIF('สินค้า'!$E$2:$E$5575,A8) | C8: =COUNTIFS('สินค้า'!$E$2:$E$5575,A8,'สินค้า'!$I$2:$I$5575,"มี") | D8: =COUNTIFS('สินค้า'!$E$2:$E$5575,A8,'สินค้า'!$M$2:$M$5575,"ตรงกัน")
A9: FOOTJOY | B9: =COUNTIF('สินค้า'!$E$2:$E$5575,A9) | C9: =COUNTIFS('สินค้า'!$E$2:$E$5575,A9,'สินค้า'!$I$2:$I$5575,"มี") | D9: =COUNTIFS('สินค้า'!$E$2:$E$5575,A9,'สินค้า'!$M$2:$M$5575,"ตรงกัน")
A10: CALVIN KLEIN | B10: =COUNTIF('สินค้า'!$E$2:$E$5575,A10) | C10: =COUNTIFS('สินค้า'!$E$2:$E$5575,A10,'สินค้า'!$I$2:$I$5575,"มี") | D10: =COUNTIFS('สินค้า'!$E$2:$E$5575,A10,'สินค้า'!$M$2:$M$5575,"ตรงกัน")
A11: WAAC | B11: =COUNTIF('สินค้า'!$E$2:$E$5575,A11) | C11: =COUNTIFS('สินค้า'!$E$2:$E$5575,A11,'สินค้า'!$I$2:$I$5575,"มี") | D11: =COUNTIFS('สินค้า'!$E$2:$E$5575,A11,'สินค้า'!$M$2:$M$5575,"ตรงกัน")
A12: NIKE | B12: =COUNTIF('สินค้า'!$E$2:$E$5575,A12) | C12: =COUNTIFS('สินค้า'!$E$2:$E$5575,A12,'สินค้า'!$I$2:$I$5575,"มี") | D12: =COUNTIFS('สินค้า'!$E$2:$E$5575,A12,'สินค้า'!$M$2:$M$5575,"ตรงกัน")
A13: CUTTER & BUCK | B13: =COUNTIF('สินค้า'!$E$2:$E$5575,A13) | C13: =COUNTIFS('สินค้า'!$E$2:$E$5575,A13,'สินค้า'!$I$2:$I$5575,"มี") | D13: =COUNTIFS('สินค้า'!$E$2:$E$5575,A13,'สินค้า'!$M$2:$M$5575,"ตรงกัน")
... A81: LE BOTANICAL | B81: =COUNTIF('สินค้า'!$E$2:$E$5575,A81) | C81: =COUNTIFS('สินค้า'!$E$2:$E$5575,A81,'สินค้า'!$I$2:$I$5575,"มี") | D81: =COUNTIFS('สินค้า'!$E$2:$E$5575,A81,'สินค้า'!$M$2:$M$5575,"ตรงกัน")
